Workbook

Sheet Extraction_Log
A1: Extract_ID | B1: Source_Type | C1: Organisation | D1: Document_Title | E1: URL | F1: Year | G1: Geo_Scope | H1: Geo_Tier | I1: UK_Data | J1: Geo_Usage | K1: Verbatim_Extract | L1: Page_Section | M1: Word_Count | N1: Initial_Code_1 | O1: Initial_Code_2 | P1: Initial_Code_3 | Q1: Coding_Level | R1: Theme_Candidate | S1: Sub_Theme | T1: Framework_Alignment | U1: Confirmation_Status | V1: Cross_Reference | W1: Confidence_Level | X1: Notes | Y1: Date_Extracted | Z1: Reviewer_Decision | AA1: Exclusion_Note
A2: EXT_ALD_001 | B2: Retailer | C2: Aldi UK | D2: Aldi UK Sustainability Report 2024 | E2: https://dm.emea.cms.aldi.cx/is/content/aldiprodeu/AL01_Aldi_2024_SR_UK | F2: 2024 | G2: UK | H2: T1_UK_Specific | I2: Yes | J2: Primary_Evidence | K2: Our automated food waste report platform shows what is wasted in granular detail, so that we can see what's discarded most often. Then each store can target their food waste reduction actions accordingly | L2: p.26 (Tackling food waste) | M2: 33 | N2: automated_waste_reporting | O2: granular_data_analysis | P2: store_level_action | Q2: First_Order | R2: TH_01 | S2: Inventory_Accuracy | T2: TOE_Tech | U2: Verified | V2: None identified | W2: High | X2: Explicit mention of a technology platform used for 'granular' analysis to drive operational action. Directly addresses RQ1 (BD technologies) and RQ2 (waste reduction impact). | Y2: 07-01-2026 | Z2: Include
A3: EXT_ALD_002 | B3: Retailer | C3: Aldi UK | D3: Aldi UK Sustainability Report 2024 | E3: https://dm.emea.cms.aldi.cx/is/content/aldiprodeu/AL01_Aldi_2024_SR_UK | F3: 2024 | G3: UK | H3: T1_UK_Specific | I3: Yes | J3: Primary_Evidence | K3: Operationally, we have exceeded our short-term KPI to reduce operational food waste by 48%, by achieving a reduction of 72% by the end of 2024 (2017 baseline). | L3: p.26 (Tackling food waste) | M3: 29 | N3: operational_waste_reduction_72pct | O3: KPI_performance_exceeded | P3: 2017_baseline | Q3: First_Order | R3: TH_02 | S3: Food_Waste_Prevention | T3: 5Vs_Value | U3: Verified | V3: Cross-checks with EXT_ALD_009 (67% to 2023) | W3: High | X3: Quantifies the success of the operational strategies (including the platform mentioned in EXT_ALD_001). 72% reduction is a significant metric for RQ2. | Y3: 07-01-2026 | Z3: Include
A4: EXT_ALD_003 | B4: Retailer | C4: Aldi UK | D4: Aldi UK Sustainability Report 2024 | E4: https://dm.emea.cms.aldi.cx/is/content/aldiprodeu/AL01_Aldi_2024_SR_UK | F4: 2024 | G4: UK | H4: T1_UK_Specific | I4: Yes | J4: Primary_Evidence | K4: The shelf life for our core beef has increased from 8 to 15 days, reducing food waste. | L4: p.31 (Positive action on packaging) | M4: 19 | N4: shelf_life_extension_7days | O4: beef_inventory_optimisation | P4: packaging_innovation | Q4: First_Order | R4: TH_01 | S4: Stock_Availability | T4: SCOR_Make | U4: Verified | V4: None identified | W4: High | X4: Demonstrates inventory optimisation through product/packaging innovation. Extending shelf life directly impacts inventory holding capability and waste (RQ2). However, there is no relation with BD application, just packaging improvements. | Y4: 07-01-2026 | Z4: Exclude | AA4: Shelf life extension via packaging, not BD technology
A5: EXT_ALD_004 | B5: Retailer | C5: Aldi UK | D5: Aldi UK Sustainability Report 2024 | E5: https://dm.emea.cms.aldi.cx/is/content/aldiprodeu/AL01_Aldi_2024_SR_UK | F5: 2024 | G5: UK | H5: T1_UK_Specific | I5: Yes | J5: Primary_Evidence | K5: Our National Real Estate team has now installed 625 water Automatic Meter Reader devices in Aldi stores, and the project will be completed by the end of 2025. These devices mean we get quality water data | L5: p.19 (Managing water supplies) | M5: 36 | N5: IoT_meter_rollout_625_stores | O5: real_time_data_acquisition | P5: leak_detection | Q5: First_Order | R5: TH_04 | S5: Data_Infrastructure | T5: TOE_Tech | U5: Verified | V5: Cross-checks with EXT_ALD_010 (595 AMS) | W5: High | X5: Evidence of IoT adoption (Automatic Meter Readers). While water-focused, it proves the deployment of data-gathering infrastructure across the store estate (RQ1). | Y5: 07-01-2026 | Z5: Exclude | AA5: Water metering infrastructure - not related to inventory/BD
A6: EXT_ALD_005 | B6: Retailer | C6: Aldi UK | D6: Aldi UK Sustainability Report 2024 | E6: https://dm.emea.cms.aldi.cx/is/content/aldiprodeu/AL01_Aldi_2024_SR_UK | F6: 2024 | G6: UK | H6: T1_UK_Specific | I6: Yes | J6: Primary_Evidence | K6: To understand the difference we can make, we use supply chain data via 3Keel, who survey our suppliers... to calculate our annual soy footprint and monitor our performance. | L6: p.15 (Tackling deforestation) | M6: 28 | N6: 3Keel_supply_chain_analytics | O6: footprint_calculation_method | P6: supplier_data_survey | Q6: First_Order | R6: TH_04 | S6: Vendor_Partnerships | T6: SCOR_Source | U6: Verified | V6: Correlates with EXT_ALD_006 (D&A Services) | W6: High | X6: Example of using third-party data analytics (3Keel) for upstream supply chain visibility. Relevant to 'Source' phase of SCOR. Addresses RQ1 (BD technologies). | Y6: 07-01-2026 | Z6: Exclude | AA6: Soy footprint supplier monitoring - sustainability focus, not inventory
A7: EXT_ALD_006 | B7: Retailer | C7: Aldi Stores Limited | D7: Annual Report and Financial Statements 2024 | E7: https://find-and-update.company-information.service.gov.uk/company/02321869/filing-history | F7: 2024 | G7: UK | H7: T1_UK_Specific | I7: Yes | J7: Primary_Evidence | K7: During the year the group received services amounting to £19.775m (2023: £15.726m) from Aldi D&A Services GmbH. | L7: p.68, Note 25 (Related Party Transactions) | M7: 20 | N7: analytics_investment_£19.8m | O7: intragroup_services | P7: YoY_growth_26pct | Q7: First_Order | R7: TH_04 | S7: Centre_of_Excellence | T7: TOE_Org | U7: Verified | V7: Correlates with EXT_ALD_005 (3Keel partnership) | W7: High | X7: CRITICAL FINANCIAL EVIDENCE: Explicit quantifying of 'D&A' (Data & Analytics) spend. The 26% YoY increase (from £15.7m) proves accelerating investment in BD capabilities. Audited by KPMG. Supports RQ1 and RQ3. | Y7: 07-01-2026 | Z7: Include
A8: EXT_ALD_007 | B8: Retailer | C8: Aldi Stores Limited | D8: Annual Report and Financial Statements 2024 | E8: https://find-and-update.company-information.service.gov.uk/company/02321869/filing-history | F8: 2024 | G8: UK | H8: T1_UK_Specific | I8: Yes | J8: Primary_Evidence | K8: Aldi is rolling out Integrated Refrigeration Facility Management (IRFM), a middleware that automates work orders from alarms and supports predictive monitoring to optimise equipment performance. The system will be fully operational by the end of the year, enabling remote monitoring and lifecycle management of equipment | L8: p.17, Table 1 (Transition Risks) | M8: 44 | N8: predictive_monitoring_IRFM | O8: middleware_automation | P8: remote_lifecycle_management | Q8: First_Order | R8: TH_01 | S8: Inventory_Accuracy | T8: TOE_Tech | U8: Verified | V8: None identified | W8: High | X8: Specific naming of a 'middleware' technology (IRFM) used for 'predictive monitoring'. This is a key example of BD/IoT application in operational maintenance. Addresses RQ1. | Y8: 07-01-2026 | Z8: Exclude | AA8: BD applied to improve equipment performance. Not related to inventory optimisation.
A9: EXT_ALD_008 | B9: Retailer | C9: Aldi Stores Limited | D9: Annual Report and Financial Statements 2024 | E9: https://find-and-update.company-information.service.gov.uk/company/02321869/filing-history | F9: 2024 | G9: UK | H9: T1_UK_Specific | I9: Yes | J9: Primary_Evidence | K9: Net cash of £599m (2023: £597m) was used in investing activities, primarily reflecting the group's investment in its store and distribution network and technology infrastructure... Purchase of intangible assets 203K. | L9: p.4, Financial key performance indicators; p45, Cash flows from investing activities | M9: 27 | N9: tech_infrastructure_investment | O9: capex_£599m | P9: distribution_network | Q9: Mixed | R9: TH_04 | S9: Data_Infrastructure | T9: TOE_Org | U9: Verified | V9: None identified | W9: High | X9: Links 'technology infrastructure' directly to the primary capital expenditure figure (£599m). The 203K spent in intangible fixed assets suggests that tech is a top-level investment priority. Supports RQ3. | Y9: 07-01-2026 | Z9: Include
A10: EXT_ALD_009 | B10: Retailer | C10: Aldi Stores Limited | D10: Annual Report and Financial Statements 2024 | E10: https://find-and-update.company-information.service.gov.uk/company/02321869/filing-history | F10: 2024 | G10: UK | H10: T1_UK_Specific | I10: Yes | J10: Primary_Evidence | K10: Between 2017 and 2023, Aldi UK has reduced food waste intensity within its own operations by 67%. | L10: p.26, Waste Management | M10: 18 | N10: waste_intensity_reduction_67pct | O10: operational_efficiency | P10: 2017_baseline | Q10: First_Order | R10: TH_02 | S10: Food_Waste_Prevention | T10: SCOR_Return | U10: Verified | V10: Cross-checks with EXT_ALD_002 (72% to 2024) | W10: High | X10: Provides a hard longitudinal metric (67% reduction to 2023) for operational waste efficiency. Consistent with EXT_ALD_002 showing 72% by 2024. Directly relevant to RQ2. | Y10: 07-01-2026 | Z10: Exclude | AA10: Superseded by EXT_ALD_002 with updated 72% figure (end 2024)
A11: EXT_ALD_010 | B11: Retailer | C11: Aldi Stores Limited | D11: Annual Report and Financial Statements 2024 | E11: https://find-and-update.company-information.service.gov.uk/company/02321869/filing-history | F11: 2024 | G11: UK | H11: T1_UK_Specific | I11: Yes | J11: Primary_Evidence | K11: In FY2024, 595 AMS were installed at Aldi at sites... This system will create alerts when leaks or unusually high consumption have been identified to speed up leak detection. Its leak detection process resulted in engineers being dispatched to Aldi sites 43 times in 2024 | L11: p.26, Water Management | M11: 41 | N11: IoT_deployment_595_sites | O11: leak_detection_alerts | P11: automated_metering | Q11: First_Order | R11: TH_01 | S11: Supply_Chain_Visibility | T11: 5Vs_Velocity | U11: Cross_Check_Required | V11: Cross-checks with EXT_ALD_004 (625 AMR) | W11: High | X11: Confirms IoT rollout scale (595 AMS sites) and demonstrates 'velocity' value (speeding up leak detection). Note: discrepancy with EXT_ALD_004 (625 AMR) - terminology difference (AMS vs AMR) or different measurement periods. Addresses RQ1. | Y11: 07-01-2026 | Z11: Exclude | AA11: It relates to sustainability, not inventory optimisation or waste reduction.
A12: EXT_ASD_001 | B12: Retailer | C12: Asda (Bellis Finco PLC) | D12: Annual Report and Consolidated Financial Statements 2024 | E12: https://find-and-update.company-information.service.gov.uk/company/12855336/filing-history | F12: 2024 | G12: UK | H12: T1_UK_Specific | I12: Yes | J12: Primary_Evidence | K12: In Project Future we are delivering a best-in-class technology stack and unlocking breakthrough advancements in Food Retail data analytics. | L12: p.12 (Financial Review) | M12: 20 | N12: project_future_analytics | O12: breakthrough_advancements | P12: tech_stack_upgrade | Q12: First_Order | R12: TH_01 | S12: ROI_Metrics | T12: TOE_Tech | U12: Verified | V12: None identified | W12: High | X12: Direct evidence of BD/Analytics being a strategic priority ('breakthrough advancements'). Links 'Project Future' specifically to data capability upgrades. Addresses RQ1. | Y12: 07-01-2026 | Z12: Include
A13: EXT_ASD_002 | B13: Retailer | C13: Asda (Bellis Finco PLC) | D13: Annual Report and Consolidated Financial Statements 2024 | E13: https://find-and-update.company-information.service.gov.uk/company/12855336/filing-history | F13: 2024 | G13: UK | H13: T1_UK_Specific | I13: Yes | J13: Primary_Evidence | K13: Approaching the end of the programme, we have already delivered significant technology enhancements in all depots, home offices as well as rolling out inventory management solutions across over 800 stores, primarily our smaller formats. | L13: p.12 (Financial Review) | M13: 33 | N13: inventory_solutions_rollout_800_stores | O13: depot_tech_enhancement | P13: small_format_focus | Q13: First_Order | R13: TH_01 | S13: Inventory_Accuracy | T13: SCOR_Plan | U13: Verified | V13: Correlates with EXT_ASD_001 (Project Future) | W13: High | X13: Quantifies the scale of the technology rollout (800 stores). Explicitly links 'technology enhancements' to 'inventory management solutions', directly addressing RQ1. | Y13: 07-01-2026 | Z13: Include
A14: EXT_ASD_003 | B14: Retailer | C14: Asda (Bellis Finco PLC) | D14: Annual Report and Consolidated Financial Statements 2024 | E14: https://find-and-update.company-information.service.gov.uk/company/12855336/filing-history | F14: 2024 | G14: UK | H14: T1_UK_Specific | I14: Yes | J14: Primary_Evidence | K14: The separation programme is one-off and non-recurring in nature, and will transition the Group to a standalone, leading edge IT infrastructure using software as a service from best-in-class digital partners. Having no legacy systems will provide significant competitive advantage, deliver operating efficiencies, enable better use of data, and agility in taking on growth opportunities and in responding to customers' needs. Project Future is expected to complete in 2025. Cumulative cash outflow to 31 December 2024 for the project was £867m.Project Future is expected to complete in 2025. Cumulative cash outflow to 31 December 2024 for the project was £867m. | L14: p.22 (Reconciliation of IFRS to Non-IFRS Measures) | M14: 19 | N14: IT_transformation_cost_£867m | O14: cumulative_cash_outflow | P14: 2025_completion_target | Q14: First_Order | R14: TH_04 | S14: Data_Infrastructure | T14: TOE_Org | U14: Verified | V14: Cross-checks with Capital Expenditure section p.15 | W14: High | X14: CRITICAL: Provides the precise financial scale of IT/Data transformation (£867m cumulative). Massive 'sunk cost' investment to enable future BD capabilities. Addresses RQ3 (scaling challenges/opportunities). | Y14: 07-01-2026 | Z14: Include
A15: EXT_ASD_004 | B15: Retailer | C15: Asda (Bellis Finco PLC) | D15: Annual Report and Consolidated Financial Statements 2024 | E15: https://find-and-update.company-information.service.gov.uk/company/12855336/filing-history | F15: 2024 | G15: UK | H15: T1_UK_Specific | I15: Yes | J15: Primary_Evidence | K15: The provision for store inventory loss at 31 December 2024 is £87.1m (2023: £140.2m). | L15: p.100 (Notes to Financial Statements, Note 1) | M15: 16 | N15: inventory_loss_provision_£87.1m | O15: YoY_loss_reduction_38pct | P15: provision_accuracy | Q15: First_Order | R15: TH_02 | S15: Shrinkage_Reduction | T15: 5Vs_Veracity | U15: Verified | V15: Potentially linked to EXT_ASD_002 (inventory solutions) | W15: High | X15: CRITICAL METRIC: Hard financial data on 'inventory loss' (shrinkage). Significant reduction from £140.2m to £87.1m (~38% reduction) suggests improved control/accuracy, potentially linked to new systems. Addresses RQ2. | Y15: 07-01-2026 | Z15: Include
A16: EXT_ASD_005 | B16: Retailer | C16: Asda (Bellis Finco PLC) | D16: Annual Report and Consolidated Financial Statements 2024 | E16: https://find-and-update.company-information.service.gov.uk/company/12855336/filing-history | F16: 2024 | G16: UK | H16: T1_UK_Specific | I16: Yes | J16: Primary_Evidence | K16: Disciplined execution and supply management minimised clearance markdown and maximised full price sales, improving margins and lowering inventory through the year. | L16: p.14 (Financial Review - Non-food) | M16: 21 | N16: inventory_reduction_outcome | O16: markdown_minimisation | P16: margin_improvement | Q16: Mixed | R16: TH_02 | S16: Markdown_Optimisation | T16: SCOR_Deliver | U16: Verified | V16: None identified | W16: High | X16: Qualitative evidence of the impact of 'supply management' (inventory control) on financial outcomes (margin, markdown). Connects inventory levels to profitability. Addresses RQ2. | Y16: 07-01-2026 | Z16: Include
A17: EXT_ASD_006 | B17: Retailer | C17: Asda (Bellis Finco PLC) | D17: Environmental, Social & Governance (ESG) Report 2024 | E17: https://asdagroceries.scene7.com/is/content/asdagroceries/Z%20FUTURE/Microsites/Corporate/Documents/ESG_Report_2024.pdf | F17: 2025 | G17: UK | H17: T1_UK_Specific | I17: Yes | J17: Primary_Evidence | K17: Asda, along with other UK supermarkets, in collaboration with the Leeds Institute of Data Analytics (LIDA) at the University of Leeds, is assessing the impact of these location-based restrictions on consumer behaviour | L17: p.6 (Healthy and Sustainable Choices) | M17: 33 | N17: LIDA_data_analytics_collaboration | O17: consumer_behaviour_assessment | P17: location_based_restrictions | Q17: First_Order | R17: TH_04 | S17: Vendor_Partnerships | T17: TOE_Env | U17: Verified | V17: None identified | W17: High | X17: Evidence of academic partnership for high-level data analytics (Leeds Institute of Data Analytics). Demonstrates use of external expertise to leverage Big Data for strategic insights. Addresses RQ1. | Y17: 07-01-2026 | Z17: Exclude | AA17: It relates to assessing customer behaviour towards unhealthy High Fat, Sugar, and Salt (HFSS) items
A18: EXT_ASD_007 | B18: Retailer | C18: Asda (Bellis Finco PLC) | D18: Environmental, Social & Governance (ESG) Report 2024 | E18: https://asdagroceries.scene7.com/is/content/asdagroceries/Z%20FUTURE/Microsites/Corporate/Documents/ESG_Report_2024.pdf | F18: 2025 | G18: UK | H18: T1_UK_Specific | I18: Yes | J18: Primary_Evidence | K18: The new packaging enables the shelf life of the product to be increased by up to 9 days, reducing waste and keeping the product fresher for longer. | L18: p.7 (Sustainable Choices) | M18: 25 | N18: shelf_life_extension_9days | O18: waste_reduction_mechanism | P18: packaging_innovation | Q18: First_Order | R18: TH_01 | S18: Stock_Availability | T18: SCOR_Make | U18: Verified | V18: Compare with EXT_ALD_003 (Aldi beef 7 days) | W18: High | X18: Shows how physical product/packaging innovation directly alters inventory parameters (shelf life), which feeds into BD algorithms for ordering/stock holding. Addresses RQ2. Compare with Aldi's 7-day extension. | Y18: 07-01-2026 | Z18: Exclude | AA18: It relats to product packaging
A19: EXT_ASD_008 | B19: Retailer | C19: Asda (Bellis Finco PLC) | D19: Environmental, Social & Governance (ESG) Report 2024 | E19: https://asdagroceries.scene7.com/is/content/asdagroceries/Z%20FUTURE/Microsites/Corporate/Documents/ESG_Report_2024.pdf | F19: 2025 | G19: UK | H19: T1_UK_Specific | I19: Yes | J19: Primary_Evidence | K19: In December 2024, Asda launched a trial with Land App... The goal is to explore how remote sensing technology can support farmers to improve soil health, reduce risks like flooding, and enhance wildlife habitats. | L19: p.10 (Nature - Land App trial) | M19: 34 | N19: remote_sensing_technology | O19: land_app_trial | P19: supply_chain_visibility | Q19: First_Order | R19: TH_04 | S19: Data_Infrastructure | T19: TOE_Tech | U19: Verified | V19: None identified | W19: High | X19: Specific mention of 'remote sensing technology' and mapping apps in upstream supply chain. Clear SCOR_Source phase data application for risk reduction. Extends data visibility to farm level. Addresses RQ1. | Y19: 07-01-2026 | Z19: Exclude | AA19: The technology mentioned relates to extended risk reduction on farms
A20: EXT_ASD_009 | B20: Retailer | C20: Asda (Bellis Finco PLC) | D20: Environmental, Social & Governance (ESG) Report 2024 | E20: https://asdagroceries.scene7.com/is/content/asdagroceries/Z%20FUTURE/Microsites/Corporate/Documents/ESG_Report_2024.pdf | F20: 2025 | G20: UK | H20: T1_UK_Specific | I20: Yes | J20: Primary_Evidence | K20: Our 2024 data shows a reduction in food waste of 15.1% YOY and 7% against our baseline. | L20: p.41 (Scorecards - Zero Waste) | M20: 19 | N20: food_waste_reduction_15.1pct | O20: YoY_performance | P20: 2024_data | Q20: First_Order | R20: TH_02 | S20: Food_Waste_Prevention | T20: SCOR_Return | U20: Verified | V20: Cross-checks with Zero Waste section p.12 | W20: High | X20: Quantified success metric (15.1% YoY reduction) resulting from 'reduction, redistribution and repurposing' strategies managed via data/inventory systems. Compare with Aldi's 72% long-term reduction. Addresses RQ2. | Y20: 07-01-2026 | Z20: Include | AA20: Page number corrected from 21 to 41
A21: EXT_ASD_010 | B21: Retailer | C21: Asda (Bellis Finco PLC) | D21: Environmental, Social & Governance (ESG) Report 2024 | E21: https://asdagroceries.scene7.com/is/content/asdagroceries/Z%20FUTURE/Microsites/Corporate/Documents/ESG_Report_2024.pdf | F21: 2025 | G21: UK | H21: T1_UK_Specific | I21: Yes | J21: Primary_Evidence | K21: Enhanced data quality has also enabled more accurate tracking and analysis of health performance across the portfolio. | L21: p.21 (Scorecards - Healthy Choices) | M21: 17 | N21: enhanced_data_quality | O21: accurate_tracking_analysis | P21: portfolio_performance | Q21: First_Order | R21: TH_04 | S21: Data_Infrastructure | T21: 5Vs_Veracity | U21: Verified | V21: None identified | W21: High | X21: Explicit acknowledgment that 'enhanced data quality' is a prerequisite for accurate analysis. Directly supports 'Veracity' aspect of 5Vs framework. Identifies data quality as an enabler. Addresses RQ3. | Y21: 07-01-2026 | Z21: Exclude | AA21: It relates to the business’s overall Health Score, the nutritional profile of products sold
A22: EXT_ICE_001 | B22: Retailer | C22: Iceland Foods Limited | D22: Financial Statements for the 52 week period ended 28 March 2025 | E22: https://find-and-update.company-information.service.gov.uk/company/01107406/filing-history | F22: 2025 | G22: UK | H22: T1_UK_Specific | I22: Yes | J22: Primary_Evidence | K22: The new Warehouse Management system has been successfully rolled out to all of our Regional Distribution Centres with the final implementation completed as planned in July 2025... using technology to support this. | L22: p.7 (Supply chain) | M22: 30 | N22: WMS_rollout_completed | O22: supply_chain_productivity | P22: RDC_technology | Q22: First_Order | R22: TH_01 | S22: Supply_Chain_Visibility | T22: TOE_Tech | U22: Verified | V22: None identified | W22: High | X22: Confirms completion of major technology infrastructure project (WMS) across all RDCs. Critical evidence for Legacy Systems being updated to modern tech. Addresses RQ1. | Y22: 07-01-2026 | Z22: Include
A23: EXT_ICE_002 | B23: Retailer | C23: Iceland Foods Limited | D23: Financial Statements for the 52 week period ended 28 March 2025 | E23: https://find-and-update.company-information.service.gov.uk/company/01107406/filing-history | F23: 2025 | G23: UK | H23: T1_UK_Specific | I23: Yes | J23: Primary_Evidence | K23: We are also introducing technology that will allow us to boost sales and reduce waste by making dynamic markdowns of products nearing the end of their shelf life. | L23: p.11 (Outlook) | M23: 25 | N23: dynamic_markdown_technology | O23: waste_reduction | P23: shelf_life_management | Q23: First_Order | R23: TH_02 | S23: Markdown_Optimisation | T23: SCOR_Return | U23: Verified | V23: Correlates with EXT_ICE_006 (Gander technology) | W23: High | X23: Explicit mention of 'dynamic markdown' technology. Specific BD/AI application for inventory clearance and waste minimisation. Addresses RQ2. | Y23: 07-01-2026 | Z23: Include
A24: EXT_ICE_003 | B24: Retailer | C24: Iceland Foods Limited | D24: Financial Statements for the 52 week period ended 28 March 2025 | E24: https://find-and-update.company-information.service.gov.uk/company/01107406/filing-history | F24: 2025 | G24: UK | H24: T1_UK_Specific | I24: Yes | J24: Primary_Evidence | K24: Our FY25 Food Waste report... showed that we had achieved a 38% reduction in food and drink waste since our baseline in FY18, and a 12% reduction from FY24. | L24: p.10 (Environmental, Social & Governance) | M24: 29 | N24: waste_reduction_38pct | O24: YoY_reduction_12pct | P24: FY25_metrics | Q24: First_Order | R24: TH_02 | S24: Food_Waste_Prevention | T24: SCOR_Return | U24: Verified | V24: Cross-checks with EXT_ICE_008 (Sustainability Report) | W24: High | X24: Hard quantification of waste reduction (38% vs FY18 baseline, 12% YoY). Validates effectiveness of inventory management and supply chain strategies. Addresses RQ2. | Y24: 07-01-2026 | Z24: Include
A25: EXT_ICE_004 | B25: Retailer | C25: Iceland Foods Limited | D25: Financial Statements for the 52 week period ended 28 March 2025 | E25: https://find-and-update.company-information.service.gov.uk/company/01107406/filing-history | F25: 2025 | G25: UK | H25: T1_UK_Specific | I25: Yes | J25: Primary_Evidence | K25: This new technology, and an increased focus on our customer insight function, has driven better than ever retention of our online customers. | L25: p.6 (Online) | M25: 20 | N25: customer_insight_focus | O25: technology_driven_retention | P25: online_performance | Q25: Mixed | R25: TH_01 | S25: Demand_Forecasting | T25: 5Vs_Value | U25: Verified | V25: None identified | W25: High | X25: Links 'technology' and 'customer insight' directly to retention metrics. Shows the 'Value' (5Vs) derived from data analytics in the online channel. Addresses RQ1. | Y25: 07-01-2026 | Z25: Include
A26: EXT_ICE_005 | B26: Retailer | C26: Iceland Foods Limited | D26: Financial Statements for the 52 week period ended 28 March 2025 | E26: https://find-and-update.company-information.service.gov.uk/company/01107406/filing-history | F26: 2025 | G26: UK | H26: T1_UK_Specific | I26: Yes | J26: Primary_Evidence | K26: Amazon customers are over 90% incremental to Iceland Online and are opening the business to a larger customer base. | L26: p.6 (Online) | M26: 18 | N26: incremental_data_90pct | O26: new_channel_analytics | P26: amazon_partnership | Q26: First_Order | R26: TH_05 | S26: Online_Competition | T26: 5Vs_Volume | U26: Verified | V26: None identified | W26: High | X26: Data-driven insight into customer segmentation. '90% incremental' proves use of data to validate channel strategy and demand sources. Addresses RQ3 (scaling opportunities). | Y26: 07-01-2026 | Z26: Include
A27: EXT_ICE_006 | B27: Retailer | C27: Iceland Foods Limited | D27: Annual Sustainability Report 2024-2025 | E27: https://sustainability.iceland.co.uk/wp-content/uploads/2025/11/24-25-ESG-Report.pdf | F27: 2025 | G27: UK | H27: T1_UK_Specific | I27: Yes | J27: Primary_Evidence | K27: Gander's technology allows customers to browse reduced items at nearby stores in real time... We trialled both of these programmes in 24/25 and saw hugely positive results. Therefore, they will be rolled out nationally in 25/26. | L27: p.17 (Food Waste Reduction Workstreams) | M27: 36 | N27: real_time_markdown_visibility | O27: Gander_app_integration | P27: national_rollout_25/26 | Q27: First_Order | R27: TH_02 | S27: Markdown_Optimisation | T27: TOE_Tech | U27: Verified | V27: Correlates with EXT_ICE_002 (dynamic markdowns) | W27: High | X27: Explicitly identifies 'Gander's technology' as enabler for real-time inventory visibility to customers. Connects Stock Availability with Markdown Optimisation. National rollout 25/26. Addresses RQ1 & RQ2. | Y27: 07-01-2026 | Z27: Include
A28: EXT_ICE_007 | B28: Retailer | C28: Iceland Foods Limited | D28: Annual Sustainability Report 2024-2025 | E28: https://sustainability.iceland.co.uk/wp-content/uploads/2025/11/24-25-ESG-Report.pdf | F28: 2025 | G28: UK | H28: T1_UK_Specific | I28: Yes | J28: Primary_Evidence | K28: To tackle our overall carbon emissions, in 2024 we introduced 'Green Mile', which is a dedicated project to reduce our scope 3 emissions by optimising load efficiency... This is a data driven project | L28: p.13 (Carbon Workstreams - Green Mile) | M28: 32 | N28: Green_Mile_project | O28: data_driven_logistics | P28: load_efficiency_optimisation | Q28: First_Order | R28: TH_02 | S28: Transport_Efficiency | T28: SCOR_Deliver | U28: Verified | V28: None identified | W28: High | X28: Identifies specific 'data driven project' (Green Mile) for logistics optimisation. Demonstrates BD use for Transport Efficiency within SCOR Deliver phase. Secondary carbon benefit noted but primary focus is load efficiency. Addresses RQ1. | Y28: 07-01-2026 | Z28: Include
A29: EXT_ICE_008 | B29: Retailer | C29: Iceland Foods Limited | D29: Annual Sustainability Report 2024-2025 | E29: https://sustainability.iceland.co.uk/wp-content/uploads/2025/11/24-25-ESG-Report.pdf | F29: 2025 | G29: UK | H29: T1_UK_Specific | I29: Yes | J29: Primary_Evidence | K29: 0.48% represents a 38% decrease in food surplus produced from our baseline year 2017/18 and a 12% reduction from our previous financial year. | L29: p.16 (Food Waste Reduction) | M29: 23 | N29: food_waste_reduction_38pct | O29: YoY_reduction_12pct | P29: operational_surplus_metric | Q29: First_Order | R29: TH_02 | S29: Food_Waste_Prevention | T29: SCOR_Return | U29: Verified | V29: Cross-checks with EXT_ICE_003 (Financial Statements) | W29: High | X29: Provides precise impact metrics (38% reduction vs 2017/18 baseline). Validates the 'Value' (5Vs) of data initiatives. Consistent with Financial Statement figure. Addresses RQ2. | Y29: 07-01-2026 | Z29: Include
A30: EXT_ICE_009 | B30: Retailer | C30: Iceland Foods Limited | D30: Annual Sustainability Report 2024-2025 | E30: https://sustainability.iceland.co.uk/wp-content/uploads/2025/11/24-25-ESG-Report.pdf | F30: 2025 | G30: UK | H30: T1_UK_Specific | I30: Yes | J30: Primary_Evidence | K30: In 2024 work started with edenseven to enhance our emissions reporting and management through their digital carbon platform, cero.earth... generate insights to support strategic decision-making. | L30: p.10 (Carbon - Overview) | M30: 24 | N30: digital_carbon_platform | O30: cero_earth_implementation | P30: strategic_insight_generation | Q30: First_Order | R30: TH_04 | S30: Data_Infrastructure | T30: TOE_Tech | U30: Verified | V30: None identified | W30: High | X30: Names specific digital platform (cero.earth) for 'strategic decision-making'. Highlights infrastructure investment required to manage data. While carbon-focused, demonstrates broader data platform adoption. Addresses RQ3. | Y30: 07-01-2026 | Z30: Exclude | AA30: Carbon emissions platform - sustainability reporting, not inventory
A31: EXT_ICE_010 | B31: Retailer | C31: Iceland Foods Limited | D31: Annual Sustainability Report 2024-2025 | E31: https://sustainability.iceland.co.uk/wp-content/uploads/2025/11/24-25-ESG-Report.pdf | F31: 2025 | G31: UK | H31: T1_UK_Specific | I31: Yes | J31: Primary_Evidence | K31: The Move to -15°C is a sustainability initiative dedicated to cutting carbon emissions in the frozen food supply chain... This requires deep collaboration across both industry and academia, which the coalition aims to enable by encouraging knowledge sharing | L31: p.13 (Partnership with Minus 15 Coalition) | M31: 36 | N31: frozen_supply_chain_temp_shift | O31: industry_academia_collaboration | P31: emission_reduction_initiative | Q31: Second_Order | R31: TH_04 | S31: Vendor_Partnerships | T31: TOE_Env | U31: Verified | V31: None identified | W31: High | X31: Highlights need for 'knowledge sharing' and 'collaboration' (TOE Environment) to change supply chain parameters. Impacts inventory storage/energy costs. Iceland-specific as frozen food specialist. Addresses RQ3. | Y31: 07-01-2026 | Z31: Exclude | AA31: Frozen food carbon initiative - sustainability, not inventory optimisation
A32: EXT_LID_001 | B32: Retailer | C32: Lidl Great Britain Limited | D32: Annual Report and Financial Statements 2025 | E32: https://find-and-update.company-information.service.gov.uk/company/02816429/filing-history | F32: 2025 | G32: UK | H32: T1_UK_Specific | I32: Yes | J32: Primary_Evidence | K32: 60% of our stores now have energy data from sub-metered service entry units reporting live, every 15 minutes into our national platform... outputs from the system are provided to regions regularly to support improved analysis. | L32: p.25 (Directors' Report - Energy) | M32: 33 | N32: energy_management_platform | O32: live_data_reporting_15min | P32: sub_metering_60pct_coverage | Q32: First_Order | R32: TH_04 | S32: Data_Infrastructure | T32: 5Vs_Velocity | U32: Verified | V32: None identified | W32: High | X32: Excellent example of 'Velocity' in Big Data: live streams of energy data every 15 minutes. 60% coverage indicates implementation in progress but significant scale. Addresses RQ1. | Y32: 08-01-2026 | Z32: Exclude | AA32: Energy sub-metering - sustainability infrastructure, not inventory
A33: EXT_LID_002 | B33: Retailer | C33: Lidl Great Britain Limited | D33: Annual Report and Financial Statements 2025 | E33: https://find-and-update.company-information.service.gov.uk/company/02816429/filing-history | F33: 2025 | G33: UK | H33: T1_UK_Specific | I33: Yes | J33: Primary_Evidence | K33: The Company also continues to issue weekly offers through its rewards app, Lidl Plus, which has now hit more than 11 million users in UK. | L33: p.4 (Strategic Report - Key Business Achievements) | M33: 25 | N33: Lidl_Plus_11m_users | O33: digital_rewards_app | P33: customer_engagement_scale | Q33: First_Order | R33: TH_01 | S33: Omnichannel_Integration | T33: 5Vs_Volume | U33: Verified | V33: None identified | W33: High | X33: Quantifies the 'Volume' of customer data available (11 million users). This app is a primary source for demand forecasting data and personalised inventory marketing. Addresses RQ1. | Y33: 08-01-2026 | Z33: Include
A34: EXT_LID_003 | B34: Retailer | C34: Lidl Great Britain Limited | D34: Annual Report and Financial Statements 2025 | E34: https://find-and-update.company-information.service.gov.uk/company/02816429/filing-history | F34: 2025 | G34: UK | H34: T1_UK_Specific | I34: Yes | J34: Primary_Evidence | K34: An initiative which was introduced to help achieve these targets is an electronic labelling system. This is estimated to save over 206 tonnes of carbon annually through paper and packaging reductions | L34: p.21 (Corporate Governance - Protecting the planet) | M34: 31 | N34: electronic_labelling_system | O34: ESL_implementation | P34: process_digitisation | Q34: First_Order | R34: TH_04 | S34: Data_Infrastructure | T34: TOE_Tech | U34: Verified | V34: None identified | W34: High | X34: Explicit mention of Electronic Shelf Labels (ESL). While framed as sustainability initiative, ESL is critical inventory pricing technology enabling dynamic markdown and real-time price updates. Secondary carbon benefit noted. Addresses RQ1. | Y34: 08-01-2026 | Z34: Include
A35: EXT_LID_004 | B35: Retailer | C35: Lidl Great Britain Limited | D35: Annual Report and Financial Statements 2025 | E35: https://find-and-update.company-information.service.gov.uk/company/02816429/filing-history | F35: 2025 | G35: UK | H35: T1_UK_Specific | I35: Yes | J35: Primary_Evidence | K35: Progress (FY2025) 33% [against target] By 2030, we will have reduced Lidl GB's food waste by 50% (relative) | L35: p.16 (Strategic Report - Performance) | M35: 19 | N35: food_waste_reduction_33pct | O35: 2030_target_progress | P35: relative_reduction | Q35: First_Order | R35: TH_02 | S35: Food_Waste_Prevention | T35: SCOR_Return | U35: Verified | V35: Cross-checks with Zero Waste narrative p.21 | W35: High | X35: Hard metric on waste reduction (33% progress toward 50% target), validating effectiveness of inventory control measures. Addresses RQ2. | Y35: 08-01-2026 | Z35: Include
A36: EXT_LID_005 | B36: Retailer | C36: Lidl Great Britain Limited | D36: Annual Report and Financial Statements 2025 | E36: https://find-and-update.company-information.service.gov.uk/company/02816429/filing-history | F36: 2025 | G36: UK | H36: T1_UK_Specific | I36: Yes | J36: Primary_Evidence | K36: Construction taking place during the period on its Belvedere distribution centre to double its capacity, along with the completion of the expansion of its Bridgend distribution centre. | L36: p.4 (Strategic Report - Enhancing presence) | M36: 26 | N36: RDC_capacity_doubling | O36: warehouse_infrastructure | P36: network_expansion | Q36: First_Order | R36: TH_04 | S36: Scalable_Architecture | T36: SCOR_Deliver | U36: Verified | V36: None identified | W36: High | X36: Physical infrastructure expansion ('doubling capacity') is prerequisite for scaling BD-driven supply chain operations. Supports SCOR Deliver phase analysis. Addresses RQ3. | Y36: 08-01-2026 | Z36: Include
A37: EXT_LID_006 | B37: Retailer | C37: Lidl Great Britain Limited | D37: The Lidl Effect: Lidl GB's socioeconomic impact FY24 | E37: https://corporate.lidl.co.uk/content/download/148017/file/Lidl%20GB%20The%20Lidl%20Effect%20SER%20FY24.pdf | F37: 2025 | G37: UK | H37: T1_UK_Specific | I37: Yes | J37: Primary_Evidence | K37: In 2024 alone, we donated 18.5 million meals through a combination of food surplus and customer donations, while continuing to invest in educational programmes | L37: p.2 (Introduction) | M37: 24 | N37: surplus_donation_18.5m_meals | O37: food_waste_diversion | P37: community_investment | Q37: First_Order | R37: TH_02 | S37: Food_Waste_Prevention | T37: SCOR_Return | U37: Verified | V37: Validated by EXT_LID_009 (Assurance Statement) | W37: High | X37: Quantifies the output of inventory management 'return' processes (donation vs waste). The 18.5m meals figure is a key outcome of inventory surplus management system. Addresses RQ2. | Y37: 08-01-2026 | Z37: Include
A38: EXT_LID_007 | B38: Retailer | C38: Lidl Great Britain Limited | D38: The Lidl Effect: Lidl GB's socioeconomic impact FY24 | E38: https://corporate.lidl.co.uk/content/download/148017/file/Lidl%20GB%20The%20Lidl%20Effect%20SER%20FY24.pdf | F38: 2025 | G38: UK | H38: T1_UK_Specific | I38: Yes | J38: Primary_Evidence | K38: British suppliers, who already supply around two-thirds of the products we sell. | L38: p.2 (Introduction) | M38: 13 | N38: British_sourcing_2/3rds | O38: supplier_localisation | P38: inventory_sourcing_strategy | Q38: First_Order | R38: TH_01 | S38: Supply_Chain_Visibility | T38: SCOR_Source | U38: Verified | V38: None identified | W38: High | X38: Sourcing 2/3rds from local suppliers impacts inventory velocity (shorter lead times) and risk. Relevant to SCOR Source and Plan phases. Addresses RQ1. | Y38: 08-01-2026 | Z38: Include
A39: EXT_LID_008 | B39: Retailer | C39: Lidl Great Britain Limited | D39: The Lidl Effect: Lidl GB's socioeconomic impact FY24 | E39: https://corporate.lidl.co.uk/content/download/148017/file/Lidl%20GB%20The%20Lidl%20Effect%20SER%20FY24.pdf | F39: 2025 | G39: UK | H39: T1_UK_Specific | I39: Yes | J39: Primary_Evidence | K39: The store's contribution will further add to the £14.5 billion in Gross Value Added (GVA) Lidl generated for the GB economy in 2024. | L39: p.2 (Introduction) | M39: 23 | N39: GVA_contribution_£14.5bn | O39: economic_impact_scale | P39: market_value_creation | Q39: First_Order | R39: TH_05 | S39: Market_Concentration | T39: 5Vs_Value | U39: Verified | V39: None identified | W39: High | X39: Shows scale of operation (£14.5bn GVA). Establishes Volume and Value context for Big Data implementation. Addresses RQ3 (scaling context). | Y39: 08-01-2026 | Z39: Include
A40: EXT_LID_009 | B40: Consultancy | C40: Forvis Mazars LLP | D40: Independent Limited Assurance Report to the Directors of Lidl Great Britain Limited | E40: https://corporate.lidl.co.uk/pdf/show/148017 | F40: 2025 | G40: UK | H40: T1_UK_Specific | I40: Yes | J40: Supporting_Evidence | K40: We have conducted a limited assurance engagement on the Subject Matter Information... disclosed in the Socio-Economic Impact Report FY24 | L40: p.1 (Assurance Statement) | M40: 19 | N40: independent_assurance_verification | O40: data_reliability_check | P40: FY24_reporting | Q40: Second_Order | R40: TH_04 | S40: Data_Infrastructure | T40: 5Vs_Veracity | U40: Verified | V40: Confirms EXT_LID_006 | W40: High | X40: Independent auditor verification of non-financial metrics (including meal donations). Increases reliability/Veracity of data extracted in EXT_LID_006. Addresses RQ3 (data governance). | Y40: 08-01-2026 | Z40: Include
...

Sheet Thematic_Codebook
A1: THEMATIC CODEBOOK - Version 2.1 (6 Themes)
A3: Theme_ID | B3: Theme_Name | C3: Description | D3: Sub_Themes | E3: Primary_RQ | F3: Extract_Count
A4: TH_01 | B4: BD_Operational_Efficiency | C4: Measurable operational improvements from BD/AI implementation | D4: Demand_Forecasting; Inventory_Accuracy; Stock_Availability; Labour_Optimisation; Supply_Chain_Visibility; Omnichannel_Integration; ROI_Metrics; Network_Efficiency | E4: RQ1 | F4: =COUNTIF(Extraction_Log!R:R,A4) -> 88
A5: TH_02 | B5: BD_Cost_Reduction | C5: Quantifiable cost savings, financial benefits, and waste reduction | D5: Food_Waste_Prevention; Markdown_Optimisation; Transport_Efficiency; Energy_Optimisation; Shrinkage_Reduction; Working_Capital_Improvement | E5: RQ2 | F5: =COUNTIF(Extraction_Log!R:R,A5) -> 56
A6: TH_03 | B6: Adoption_Barriers | C6: Factors impeding or slowing BD/AI implementation | D6: Technical_Complexity; Skills_Gap; Legacy_Systems; Implementation_Cost; Data_Quality_Issues; Data_Governance; Change_Resistance; Integration_Challenges | E6: RQ3 | F6: =COUNTIF(Extraction_Log!R:R,A6) -> 49
A7: TH_04 | B7: Implementation_Enablers | C7: Factors facilitating successful BD/AI adoption | D7: Leadership_Support; Vendor_Partnerships; Data_Infrastructure; Cloud_Adoption; Talent_Development; Scalable_Architecture; Centre_of_Excellence; Pilot_Programme_Success | E7: RQ3 | F7: =COUNTIF(Extraction_Log!R:R,A7) -> 51
A8: TH_05 | B8: Competitive_Dynamics | C8: How BD/AI affects competitive positioning and market structure | D8: Market_Concentration; Discounter_Pressure; Online_Competition; Technology_Differentiation; First_Mover_Advantage; Capability_Gap | E8: RQ1, RQ3 | F8: =COUNTIF(Extraction_Log!R:R,A8) -> 28
A9: TH_06 | B9: UK_Market_Context | C9: UK-specific market conditions affecting BD adoption | D9: Regulatory_Environment; Labour_Market; Consumer_Behaviour; Brexit_Impact; Inflation_Pressure; Channel_Dynamics | E9: RQ1, RQ2, RQ3 | F9: =COUNTIF(Extraction_Log!R:R,A9) -> 31

Sheet Geographic_Tiering
A1: GEOGRAPHIC TIERING FRAMEWORK
A3: Tier | B3: Code | C3: Criteria | D3: Citation Framing | E3: Usage
A4: Tier 1 | B4: T1_UK_Specific | C4: UK retailers named; UK market data; UK government sources | D4: "In the UK context..." | E4: Primary_Evidence
A5: Tier 2 | B5: T2_UK_Applicable | C5: European studies with UK explicitly in sample | D5: "European research including UK shows..." | E5: Supporting_Evidence
A6: Tier 3 | B6: T3_Transferable | C6: US/Global studies on comparable retail contexts | D6: "International evidence suggests..." | E6: Comparative
A7: Tier 4 | B7: T4_Conceptual | C7: Theoretical frameworks; methodology studies | D7: "The framework proposed by..." | E7: Conceptual_Only

Sheet Validation_Tracker
A1: VALIDATION TRACKER - UKRIO Research Integrity
A3: Claim | B3: Primary_Source | C3: Confirming_Source | D3: Status | E3: Discrepancy_Notes | F3: Resolution
A4: 72% operational food waste reduction (2017-2024) | B4: EXT_ALD_002 (Sustainability Report) | C4: EXT_ALD_009 (Financial - 67% to 2023) | D4: Verified | E4: 67% to 2023, then 72% by 2024 - consistent progression | F4: Both figures valid; cite 72% as latest with 67% as trajectory
A5: £19.775m D&A Services spend (2024) | B5: EXT_ALD_006 (Financial Statements) | C5: Single source (KPMG audited) | D5: Verified | E5: No independent confirmation available | F5: Use as primary evidence; note audited status
A6: 625 water AMR devices installed | B6: EXT_ALD_004 (Sustainability Report) | C6: EXT_ALD_010 (Financial - 595 AMS) | D6: Cross_Check_Required | E6: Sustainability=625 AMR, Financial=595 AMS | F6: Clarify: AMR vs AMS terminology; possible different measurement periods
A7: IRFM predictive monitoring system | B7: EXT_ALD_007 (Financial Statements) | C7: Single source | D7: Verified | E7: Specific middleware named | F7: Strong evidence of BD technology deployment
A8: £599m investing activities incl. tech | B8: EXT_ALD_008 (Financial Statements) | C8: KPMG audited | D8: Verified | E8: Aggregated figure (tech + stores + distribution) | F8: Use cautiously; tech portion not isolated
A9: £867m Project Future IT transformation cost | B9: EXT_ASD_003 (Financial Statements) | C9: Cross-checks with Capital Expenditure p.15 | D9: Verified | E9: Single source but audited; no independent confirmation | F9: Use as primary evidence for transformation scale
A10: Inventory loss reduction £140.2m to £87.1m (38%) | B10: EXT_ASD_004 (Financial Statements) | C10: Correlates with EXT_ASD_002 (inventory solutions rollout) | D10: Verified | E10: Timing aligns with 800-store inventory system rollout | F10: Strong evidence of BD impact on shrinkage
A11: 15.1% YoY food waste reduction | B11: EXT_ASD_009 (ESG Report) | C11: Cross-checks with Zero Waste section p.12 | D11: Verified | E11: Single year metric; compare with Aldi's longitudinal data | F11: Use alongside Aldi's 72% (2017-2024) for comparison
A12: Shelf life extension 9 days (packaging) | B12: EXT_ASD_007 (ESG Report) | C12: Compare with EXT_ALD_003 (Aldi 7 days) | D12: Verified | E12: Similar approach across retailers | F12: Evidence of industry-wide inventory optimisation trend
A13: 800 stores inventory management solutions | B13: EXT_ASD_002 (Financial Statements) | C13: Links to EXT_ASD_001 (Project Future) | D13: Verified | E13: Primarily small formats; scale for large stores unclear | F13: Note format limitation in analysis
A14: 38% food waste reduction (FY18-FY25) | B14: EXT_ICE_003 (Financial Statements) | C14: EXT_ICE_008 (Sustainability Report) | D14: Verified | E14: Both sources report identical 38% figure; 12% YoY consistent | F14: Strong cross-validated evidence
... A99: 1/3 companies at survival risk | B99: EXT_ACC_011 (Accenture) | C99: Cross-checks with Marsh | D99: Verified | E99: Existential threat | F99: Maturity <25%

Sheet Summary_Statistics
A1: EXTRACTION SUMMARY STATISTICS
A3: Metric | B3: Count
A4: Total Extracts | B4: 302
A6: BY GEOGRAPHIC TIER
A7: T1_UK_Specific | B7: =COUNTIF(Extraction_Log!H:H,"T1_UK_Specific") -> 196
A8: T2_UK_Applicable | B8: =COUNTIF(Extraction_Log!H:H,"T2_UK_Applicable") -> 12
A9: T3_Transferable | B9: =COUNTIF(Extraction_Log!H:H,"T3_Transferable") -> 80
A10: T4_Conceptual | B10: =COUNTIF(Extraction_Log!H:H,"T4_Conceptual") -> 3
A12: BY THEME
A13: TH_01 (BD_Operational_Efficiency) | B13: =COUNTIF(Extraction_Log!R:R,"TH_01") -> 88
A14: TH_02 (BD_Cost_Reduction) | B14: =COUNTIF(Extraction_Log!R:R,"TH_02") -> 56
A15: TH_03 (Adoption_Barriers) | B15: =COUNTIF(Extraction_Log!R:R,"TH_03") -> 49
A16: TH_04 (Implementation_Enablers) | B16: =COUNTIF(Extraction_Log!R:R,"TH_04") -> 51
A17: TH_05 (Competitive_Dynamics) | B17: =COUNTIF(Extraction_Log!R:R,"TH_05") -> 28
A18: TH_06 (UK_Market_Context) | B18: =COUNTIF(Extraction_Log!R:R,"TH_06") -> 31
A20: BY CONFIDENCE LEVEL
A21: High | B21: =COUNTIF(Extraction_Log!W:W,"High") -> 259
A22: Medium | B22: =COUNTIF(Extraction_Log!W:W,"Medium") -> 43
A23: Low | B23: =COUNTIF(Extraction_Log!W:W,"Low") -> 1
A25: BY FRAMEWORK ALIGNMENT
A26: TOE_Tech | B26: =COUNTIF(Extraction_Log!T:T,"TOE_Tech") -> 44
A27: TOE_Org | B27: =COUNTIF(Extraction_Log!T:T,"TOE_Org") -> 36
A28: TOE_Env | B28: =COUNTIF(Extraction_Log!T:T,"TOE_Env") -> 56
A29: SCOR_Plan | B29: =COUNTIF(Extraction_Log!T:T,"SCOR_Plan") -> 17
A30: SCOR_Source | B30: =COUNTIF(Extraction_Log!T:T,"SCOR_Source") -> 23
A31: SCOR_Make | B31: =COUNTIF(Extraction_Log!T:T,"SCOR_Make") -> 8
A32: SCOR_Deliver | B32: =COUNTIF(Extraction_Log!T:T,"SCOR_Deliver") -> 13
A33: SCOR_Return | B33: =COUNTIF(Extraction_Log!T:T,"SCOR_Return") -> 25
A34: 5Vs_Volume | B34: =COUNTIF(Extraction_Log!T:T,"5Vs_Volume") -> 8
A35: 5Vs_Velocity | B35: =COUNTIF(Extraction_Log!T:T,"5Vs_Velocity") -> 12
A36: 5Vs_Variety | B36: =COUNTIF(Extraction_Log!T:T,"5Vs_Variety") -> 8
A37: 5Vs_Veracity | B37: =COUNTIF(Extraction_Log!T:T,"5Vs_Veracity") -> 18
A38: 5Vs_Value | B38: =COUNTIF(Extraction_Log!T:T,"5Vs_Value") -> 35
A39: Multiple | B39: =COUNTIF(Extraction_Log!T:T,"Multiple") -> 0
A41: BY CONFIRMATION STATUS
A42: Verified | B42: =COUNTIF(Extraction_Log!U:U,"Verified") -> 302
A43: Pending | B43: =COUNTIF(Extraction_Log!U:U,"Pending") -> 0
A44: Cross_Check_Required | B44: =COUNTIF(Extraction_Log!U:U,"Cross_Check_Required") -> 1
A45: Contradicted | B45: =COUNTIF(Extraction_Log!U:U,"Contradicted") -> 0

Sheet Dropdown_Reference
A1: DROPDOWN VALIDATION REFERENCE
A3: Column | B3: Field | C3: Valid Values
A4: B | B4: Source_Type | C4: Consultancy, Trade_Association, Government, Academic, Retailer, Vendor, News
A5: G | B5: Geo_Scope | C5: UK, Europe, US, Global, Multiple
A6: H | B6: Geo_Tier | C6: T1_UK_Specific, T2_UK_Applicable, T3_Transferable, T4_Conceptual
A7: I | B7: UK_Data | C7: Yes, No, Partial, Unknown
A8: J | B8: Geo_Usage | C8: Primary_Evidence, Supporting_Evidence, Comparative, Conceptual_Only
A9: Q | B9: Coding_Level | C9: First_Order, Second_Order, Mixed
A10: R | B10: Theme_Candidate | C10: TH_01, TH_02, TH_03, TH_04, TH_05, TH_06
A11: T | B11: Framework_Alignment | C11: TOE_Tech, TOE_Org, TOE_Env, SCOR_Plan, SCOR_Source, SCOR_Make, SCOR_Deliver, SCOR_Return, 5Vs_Volume, 5Vs_Velocity, 5Vs_Variety, 5Vs_Veracity, 5Vs_Value, Multiple, None
A12: U | B12: Confirmation_Status | C12: Verified, Pending, Cross_Check_Required, Rejected, Contradicted
A13: W | B13: Confidence_Level | C13: High, Medium, Low
A14: Z | B14: Reviewer_Decision | C14: Include, Exclude, Merge, Refine, Flagged

Sheet Sheet1
A1: everyone to fight food waste together. The Too Good To Go app is the world's largest marketplace for surplus food, and through it we sell our unsold food in 'Surprise Bags' for local users to collect in store. We have saved over 1 million Surprise Bags from going to waste since 2023 - an equivalent of more than 5,000 tonnes of food, and saved our customers over £9 million.
